INFO:root:Message: µÈ´ý³¬Ê±

2021-08-13 15:06:40,631 - __main__ - INFO - This is a log info
2021-08-13 15:06:40,631 - __main__ - WARNING - Warning exists
2021-08-13 15:06:40,631 - __main__ - INFO - Finish
2021-08-13 15:09:35,395 - __main__ - INFO -test- This is a log info
2021-08-13 15:09:35,395 - __main__ - WARNING -test- Warning exists
2021-08-13 15:09:35,395 - __main__ - INFO -test- Finish
2021-08-13 15:10:08,147 - __main__ -test - INFO- This is a log info
2021-08-13 15:10:08,148 - __main__ -test - WARNING- Warning exists
2021-08-13 15:10:08,148 - __main__ -test - INFO- Finish
2021-08-13 15:16:18,289 - __main__ -test - INFO- This is a log info
2021-08-13 15:16:18,289 - __main__ -test - WARNING- Warning exists
2021-08-13 15:16:18,289 - root -test - ERROR- this is a error info
2021-08-13 15:16:18,290 - __main__ -test - INFO- Finish
2021-08-13 15:17:11,897 - __main__ -test - INFO- This is a log info
2021-08-13 15:17:11,897 - __main__ -test - WARNING- Warning exists
2021-08-13 15:17:11,897 - root -test - ERROR- this is a error info
2021-08-13 15:17:11,897 - __main__ -test - INFO-----------------------------------------------------------------------------------------------------
2021-08-13 15:17:53,542 - __main__ -test - INFO- This is a log info
2021-08-13 15:17:53,542 - __main__ -test - WARNING- Warning exists
2021-08-13 15:17:53,542 - root -test - ERROR- this is a error info
2021-08-13 15:17:53,543 - __main__ -test - INFO- >>>>>>>>>>>>>>>>>>>>>>>>>>>>>>>>>>>>>>>>>>>>>>>>>>>>>>>>>>>>>>>>>>>>>>>>>>>>>>>>
2021-08-13 15:19:54,788 - __main__ -test - INFO- This is a log info
2021-08-13 15:19:54,789 - __main__ -test - WARNING- Warning exists
2021-08-13 15:19:54,789 - root -test - ERROR- this is a error info
2021-08-13 15:19:54,789 - __main__ -test - INFO- >>>>>>>>>>>>>>>>>>>>>>>>>>>>>>>>>>>>>>>>>>>>>>>>>>>>>>>>>>>>>>>>>>>>>>>>>>>>>>>>
2021-08-13 15:21:34,707 - __main__ -test - INFO- this is info
2021-08-13 15:25:34,506 - __main__ -test - ERROR- this is error
Traceback (most recent call last):
  File "F:/Python38 Project/baiduUiPO/test.py", line 11, in write_logs_to_file
    result = 10 / 0
ZeroDivisionError: division by zero
2021-08-13 15:25:34,507 - __main__ -test - INFO- finished
2021-08-13 15:26:21,193 - __main__ -test - ERROR- this is error
Traceback (most recent call last):
  File "F:/Python38 Project/baiduUiPO/test.py", line 11, in write_logs_to_file
    result = 10 / 0
ZeroDivisionError: division by zero
2021-08-13 15:26:21,194 - __main__ -test - INFO- >>>>>>>>>>>>>>>>>>>>>>>>>>>>>>>>>>>>>>>>>>>>>>>>>>>>>>>>>>>>>>>>>>>>>>>>>>>>>>>>>>>>>>>>>>
2021-08-13 15:26:28,225 - __main__ -test - ERROR- this is error
Traceback (most recent call last):
  File "F:/Python38 Project/baiduUiPO/test.py", line 11, in write_logs_to_file
    result = 10 / 0
ZeroDivisionError: division by zero
2021-08-13 15:26:28,225 - __main__ -test - INFO- >>>>>>>>>>>>>>>>>>>>>>>>>>>>>>>>>>>>>>>>>>>>>>>>>>>>>>>>>>>>>>>>>>>>>>>>>>>>>>>>>>>>>>>>>>
2021-08-13 15:36:31,411 - __main__ -test - ERROR- error
Traceback (most recent call last):
  File "F:/Python38 Project/baiduUiPO/test.py", line 11, in write_logs_to_file
    result = 10 / 0
ZeroDivisionError: division by zero
2021-08-13 15:36:31,412 - __main__ -test - INFO- >>>>>>>>>>>>>>>>>>>>>>>>>>>>>>>>>>>>>>>>>>>>>>>>>>>>>>>>>>>>>>>>>>>>>>>>>>>>>>>>>>>>>>>>>>
2021-08-13 15:37:17,039 - __main__ -test - ERROR- error
Traceback (most recent call last):
  File "F:/Python38 Project/baiduUiPO/test.py", line 11, in write_logs_to_file
    result = 10 / 0
ZeroDivisionError: division by zero
2021-08-13 15:37:17,039 - __main__ -test - INFO- >>>>>>>>>>>>>>>>>>>>>>>>>>>>>>>>>>>>>>>>>>>>>>>>>>>>>>>>>>>>>>>>>>>>>>>>>>>>>>>>>>>>>>>>>>
2021-08-13 15:40:28,109 - __main__ -test - ERROR- error
Traceback (most recent call last):
  File "F:/Python38 Project/baiduUiPO/test.py", line 29, in <module>
    result = 10 / 0
ZeroDivisionError: division by zero
2021-08-13 15:40:28,109 - __main__ -test - INFO- >>>>>>>>>>>>>>>>>>>>>>>>>>>>>>>>>>>>>>>>>>>>>>>>>>>>>>>>>>>>>>>>>>>>>>>>>>>>>>>>>>>>>>>>>>
